Workbook

Sheet Inicio
B2: Plantilla de operaciones de flota
B3: Una sola fuente de verdad para conductores, vehículos, rutas, el plan del día e incidencias. Para Google Sheets o Excel, sin programar.
B5: Cómo empezar (más o menos 1 hora)
B6: 1. Llena las pestañas maestras | C6: Conductores, Vehículos y Rutas. Una fila cada uno. Las filas amarillas son EJEMPLOS: sobrescríbelas o bórralas.
B7: 2. No escribas texto libre donde hay lista desplegable | C7: Estados, tipos y códigos de motivo salen de la pestaña Listas. Un valor incorrecto se rechaza a propósito.
B8: 3. Cada día, usa la pestaña Hoy | C8: Una fila por ruta: fecha, ruta, conductor, vehículo y paradas. Actualiza paradas_hechas y estado en cada control.
B9: 4. Registra cada problema en Incidencias | C9: Una fila por incidencia, siempre con un código de motivo. Así aparecen los patrones más adelante.
B10: 5. Lee las verificaciones | C10: verificacion_asignacion, verificacion_datos y revision_previa se ponen en rojo cuando algo no cuadra. Corrige la causa, no ocultes el mensaje.
B11: 6. Registra la revisión previa de cada vehículo | C11: En la pestaña Revision_previa, una fila por vehículo y por salida (a mano o con un formulario de Google). Hoy muestra si el vehículo salió Apto, No apto o Sin revisión.
B12: 7. Cada semana, abre Resumen | C12: Cambia las fechas Desde y Hasta y revisa rutas atrasadas, incidencias abiertas y el gráfico por motivo.
B14: Las 6 reglas para mantener los datos limpios
B15: Regla 1: los ID son permanentes | C15: Un ID nunca cambia ni se reutiliza. Si un conductor se va, ponlo como Inactivo; no borres la fila.
B16: Regla 2: el ID se escribe una sola vez | C16: En los demás lugares lo eliges de la lista, así nombres e ID no se desfasan.
B17: Regla 3: solo valores fijos | C17: Estado, tipo de vehículo, gravedad y código de motivo salen de las listas. Para añadir un valor, agrégalo primero en Listas.
B18: Regla 4: una fila = una cosa | C18: Un conductor, un vehículo, una ruta, una salida del día, una incidencia. Sin celdas combinadas y sin notas en la columna del ID.
B19: Regla 5: toda ruta atrasada o en riesgo lleva código de motivo | C19: Si hay varias causas, anota la principal y explica el resto en notas.
B20: Regla 6: un responsable | C20: Nombra a una persona que pueda cambiar las pestañas maestras. El resto solo edita Hoy e Incidencias.
B22: Formato de los ID
B23: Conductor | C23: D + número | D23: D01, D02, ... D24
B24: Vehículo | C24: V + número | D24: V01, V02, ... V24
B25: Ruta | C25: letras del tipo + número | D25: BK-01 (moto), VN-01 (furgoneta), TR-01 (camión)
B26: Incidencia | C26: EX- + 4 dígitos | D26: EX-0001, EX-0002, ...
B27: Nota | C27: Los prefijos BK, VN, TR y EX se mantienen para que esta plantilla coincida con los datos y tableros de ejemplo.
B29: Colores
B30: Encabezado azul oscuro | C30: Aquí escribes o eliges valores.
B31: Encabezado gris | C31: Se calcula solo. No escribas aquí, es una fórmula.
B32: Fila amarillo claro | C32: Fila de ejemplo. Sobrescríbela con tus datos reales.
B33: Texto en rojo | C33: Falló una verificación o hay un ID duplicado.
B35: Códigos de motivo (lista completa en la pestaña Listas)
B36: TRA CLI AVE INC | C36: Tráfico, clima, avería, accidente o incidente
B37: AUS DIR ACE REC | C37: Cliente ausente, problema de dirección, acceso bloqueado, entrega rechazada
B38: PLA CON VEH OTR | C38: Plan muy ajustado, problema del conductor, vehículo no listo, otro (explicar en notas)
B40: Notas y límites
B41: Filas preparadas | C41: Cada pestaña viene lista para 300 filas. Si necesitas más, copia la última fila hacia abajo.
B42: Usarla en Google Sheets | C42: Sube el archivo a Google Drive y ábrelo con Google Sheets. Las listas, los colores y las fórmulas deberían mantenerse, pero prueba una lista y una verificación antes de depender de ellas.
B43: Datos personales | C43: Los teléfonos y las fechas de licencia son datos personales. Limita quién puede abrir la pestaña Conductores y sigue las reglas de tu empresa.
B44: Los ejemplos son ficticios | C44: Todos los nombres, placas y teléfonos de este archivo son inventados.

Sheet Resumen
B2: Resumen semanal
B3: Se calcula solo a partir de Hoy, Incidencias, Revision_previa, Vehículos y Conductores. No escribas en las celdas con fórmula.
B5: Desde | C5: 46300 | D5: ← Cambia estas dos fechas para ver otra semana u otro período (celdas azul claro).
B6: Hasta | C6: 46306
B7: Rutas e incidencias del período
B8: Medida | C8: Valor | D8: Qué significa
B9: Rutas registradas | C9: =COUNTIFS(Hoy!$A:$A,">="&$C$5,Hoy!$A:$A,"<="&$C$6,Hoy!$B:$B,"<>") -> 4 | D9: Filas de Hoy en el período
B10: Paradas planificadas | C10: =SUMIFS(Hoy!$H:$H,Hoy!$A:$A,">="&$C$5,Hoy!$A:$A,"<="&$C$6) -> 72 | D10: Suma de paradas_planificadas
B11: Paradas hechas | C11: =SUMIFS(Hoy!$I:$I,Hoy!$A:$A,">="&$C$5,Hoy!$A:$A,"<="&$C$6) -> 22 | D11: Suma de paradas_hechas
B12: Cumplimiento de paradas | C12: =IF(C10=0,"",C11/C10) -> 0.30555556 | D12: Hechas entre planificadas. Útil con días ya cerrados; un día en curso saldrá bajo
B13: Rutas finalizadas | C13: =COUNTIFS(Hoy!$A:$A,">="&$C$5,Hoy!$A:$A,"<="&$C$6,Hoy!$K:$K,"Finalizada") -> 0 | D13: Estado Finalizada
B14: Rutas atrasadas | C14: =COUNTIFS(Hoy!$A:$A,">="&$C$5,Hoy!$A:$A,"<="&$C$6,Hoy!$K:$K,"Atrasada") -> 1 | D14: Estado Atrasada
B15: Rutas en riesgo | C15: =COUNTIFS(Hoy!$A:$A,">="&$C$5,Hoy!$A:$A,"<="&$C$6,Hoy!$K:$K,"En riesgo") -> 1 | D15: Estado En riesgo
B16: Rutas canceladas | C16: =COUNTIFS(Hoy!$A:$A,">="&$C$5,Hoy!$A:$A,"<="&$C$6,Hoy!$K:$K,"Cancelada") -> 0 | D16: Estado Cancelada
B17: Incidencias registradas | C17: =COUNTIFS(Incidencias!$B:$B,">="&$C$5,Incidencias!$B:$B,"<="&$C$6) -> 1 | D17: Filas de Incidencias en el período
B18: Incidencias abiertas | C18: =COUNTIFS(Incidencias!$B:$B,">="&$C$5,Incidencias!$B:$B,"<="&$C$6,Incidencias!$L:$L,"Abierta") -> 0 | D18: Estado Abierta: alguien debe cerrarlas
B19: Incidencias de gravedad alta | C19: =COUNTIFS(Incidencias!$B:$B,">="&$C$5,Incidencias!$B:$B,"<="&$C$6,Incidencias!$H:$H,"Alta") -> 0 | D19: Gravedad Alta
B20: Revisiones previas realizadas | C20: =COUNTIFS(Revision_previa!$A:$A,">="&$C$5,Revision_previa!$A:$A,"<"&($C$6+1)) -> 3 | D20: Filas de Revision_previa en el período
B21: Fallas halladas en revisiones previas | C21: =COUNTIFS(Revision_previa!$A:$A,">="&$C$5,Revision_previa!$A:$A,"<"&($C$6+1),Revision_previa!$D:$D,"Falla")+COUNTIFS(Revision_previa!$A:$A,">="&$C$5,Revision_previa!$A:$A,"<"&($C$6+1),Revision_previa!$E:$E,"Falla")+COUNTIFS(Revision_previa!$A:$A,">="&$C$5,Revision_previa!$A:$A,"<"&($C$6+1),Revision_previa!$F:$F,"Falla")+COUNTIFS(Revision_previa!$A:$A,">="&$C$5,Revision_previa!$A:$A,"<"&($C$6+1),Revision_previa!$H:$H,"Encendido") -> 1 | D21: Neumáticos, luces, frenos con Falla y testigos Encendidos
B23: Flota hoy (no depende del período)
B24: Medida | C24: Valor | D24: Qué significa
B25: Vehículos Disponibles | C25: =COUNTIF(Vehículos!$E:$E,"Disponible") -> 2 | D25: Listos para asignar
B26: Vehículos En uso | C26: =COUNTIF(Vehículos!$E:$E,"En uso") -> 1 | D26: Ya asignados
B27: Vehículos en Taller | C27: =COUNTIF(Vehículos!$E:$E,"Taller") -> 1 | D27: No se pueden asignar
B28: Vehículos Fuera de servicio | C28: =COUNTIF(Vehículos!$E:$E,"Fuera de servicio") -> 0 | D28: Retirados
B29: Servicios que vencen en 7 días o ya vencidos | C29: =COUNTIF(Vehículos!$F:$F,"<"&(TODAY()+7)) -> 1 | D29: Programa el mantenimiento
B30: Licencias que vencen en 30 días o ya vencidas | C30: =COUNTIF(Conductores!$H:$H,"<"&(TODAY()+30)) -> 0 | D30: Avisa al conductor y al responsable
B31: Conductores Activos | C31: =COUNTIF(Conductores!$G:$G,"Activo") -> 4 | D31: Disponibles para asignar
B33: Incidencias por código de motivo
B34: Motivo | C34: Incidencias | D34: Qué significa | E34: % del total | F34: Barra
B35: =Listas!$O$2&" - "&Listas!$P$2 -> TRA - Tráfico o cierre de vía | C35: =COUNTIFS(Incidencias!$B:$B,">="&$C$5,Incidencias!$B:$B,"<="&$C$6,Incidencias!$F:$F,Listas!$O$2) -> 1 | D35: =Listas!$Q$2 -> Vías lentas, accidente adelante, calle cerrada | E35: =IF(SUM($C$35:$C$46)=0,"",C35/SUM($C$35:$C$46)) -> 1 | F35: =IF(E35="","",REPT("█",ROUND(E35*30,0))) -> ██████████████████████████████
B36: =Listas!$O$3&" - "&Listas!$P$3 -> CLI - Clima | C36: =COUNTIFS(Incidencias!$B:$B,">="&$C$5,Incidencias!$B:$B,"<="&$C$6,Incidencias!$F:$F,Listas!$O$3) -> 0 | D36: =Listas!$Q$3 -> Lluvia, tormenta, inundación | E36: =IF(SUM($C$35:$C$46)=0,"",C36/SUM($C$35:$C$46)) -> 0 | F36: =IF(E36="","",REPT("█",ROUND(E36*30,0)))
B37: =Listas!$O$4&" - "&Listas!$P$4 -> AVE - Avería del vehículo | C37: =COUNTIFS(Incidencias!$B:$B,">="&$C$5,Incidencias!$B:$B,"<="&$C$6,Incidencias!$F:$F,Listas!$O$4) -> 0 | D37: =Listas!$Q$4 -> Falla mecánica, goma ponchada, sin combustible | E37: =IF(SUM($C$35:$C$46)=0,"",C37/SUM($C$35:$C$46)) -> 0 | F37: =IF(E37="","",REPT("█",ROUND(E37*30,0)))
B38: =Listas!$O$5&" - "&Listas!$P$5 -> INC - Accidente o incidente | C38: =COUNTIFS(Incidencias!$B:$B,">="&$C$5,Incidencias!$B:$B,"<="&$C$6,Incidencias!$F:$F,Listas!$O$5) -> 0 | D38: =Listas!$Q$5 -> Choque, lesión, robo, problema de seguridad | E38: =IF(SUM($C$35:$C$46)=0,"",C38/SUM($C$35:$C$46)) -> 0 | F38: =IF(E38="","",REPT("█",ROUND(E38*30,0)))
B39: =Listas!$O$6&" - "&Listas!$P$6 -> AUS - Cliente ausente | C39: =COUNTIFS(Incidencias!$B:$B,">="&$C$5,Incidencias!$B:$B,"<="&$C$6,Incidencias!$F:$F,Listas!$O$6) -> 0 | D39: =Listas!$Q$6 -> Nadie para recibir la entrega | E39: =IF(SUM($C$35:$C$46)=0,"",C39/SUM($C$35:$C$46)) -> 0 | F39: =IF(E39="","",REPT("█",ROUND(E39*30,0)))
B40: =Listas!$O$7&" - "&Listas!$P$7 -> DIR - Problema de dirección | C40: =COUNTIFS(Incidencias!$B:$B,">="&$C$5,Incidencias!$B:$B,"<="&$C$6,Incidencias!$F:$F,Listas!$O$7) -> 0 | D40: =Listas!$Q$7 -> Dirección errónea, incompleta o imposible de encontrar | E40: =IF(SUM($C$35:$C$46)=0,"",C40/SUM($C$35:$C$46)) -> 0 | F40: =IF(E40="","",REPT("█",ROUND(E40*30,0)))
B41: =Listas!$O$8&" - "&Listas!$P$8 -> ACE - Acceso bloqueado | C41: =COUNTIFS(Incidencias!$B:$B,">="&$C$5,Incidencias!$B:$B,"<="&$C$6,Incidencias!$F:$F,Listas!$O$8) -> 0 | D41: =Listas!$Q$8 -> Portón, edificio o calle sin acceso | E41: =IF(SUM($C$35:$C$46)=0,"",C41/SUM($C$35:$C$46)) -> 0 | F41: =IF(E41="","",REPT("█",ROUND(E41*30,0)))
B42: =Listas!$O$9&" - "&Listas!$P$9 -> REC - Entrega rechazada | C42: =COUNTIFS(Incidencias!$B:$B,">="&$C$5,Incidencias!$B:$B,"<="&$C$6,Incidencias!$F:$F,Listas!$O$9) -> 0 | D42: =Listas!$Q$9 -> El cliente rechaza la entrega | E42: =IF(SUM($C$35:$C$46)=0,"",C42/SUM($C$35:$C$46)) -> 0 | F42: =IF(E42="","",REPT("█",ROUND(E42*30,0)))
B43: =Listas!$O$10&" - "&Listas!$P$10 -> PLA - Plan muy ajustado | C43: =COUNTIFS(Incidencias!$B:$B,">="&$C$5,Incidencias!$B:$B,"<="&$C$6,Incidencias!$F:$F,Listas!$O$10) -> 0 | D43: =Listas!$Q$10 -> La ruta tenía demasiadas paradas o tiempos poco realistas | E43: =IF(SUM($C$35:$C$46)=0,"",C43/SUM($C$35:$C$46)) -> 0 | F43: =IF(E43="","",REPT("█",ROUND(E43*30,0)))
B44: =Listas!$O$11&" - "&Listas!$P$11 -> CON - Problema del conductor | C44: =COUNTIFS(Incidencias!$B:$B,">="&$C$5,Incidencias!$B:$B,"<="&$C$6,Incidencias!$F:$F,Listas!$O$11) -> 0 | D44: =Listas!$Q$11 -> Ausente, salida tardía, enfermo, perdido | E44: =IF(SUM($C$35:$C$46)=0,"",C44/SUM($C$35:$C$46)) -> 0 | F44: =IF(E44="","",REPT("█",ROUND(E44*30,0)))
...

Sheet Hoy
A1: fecha | B1: id_ruta | C1: id_conductor | D1: id_vehiculo | E1: nombre_conductor | F1: zona | G1: verificacion_asignacion | H1: paradas_planificadas | I1: paradas_hechas | J1: avance | K1: estado | L1: codigo_motivo | M1: ultimo_control | N1: notas | O1: verificacion_datos | P1: revision_previa
A2: 46304 | B2: BK-01 | C2: D01 | D2: V01 | E2: =IF(C2="","",IFERROR(INDEX(Conductores!$B:$B,MATCH(C2,Conductores!$A:$A,0)),"ID no encontrado")) -> Juan Martínez | F2: =IF(B2="","",IFERROR(INDEX(Rutas!$B:$B,MATCH(B2,Rutas!$A:$A,0)),"ID no encontrado")) -> Distrito Nacional | G2: =IF(OR(B2="",C2="",D2=""),"",IF(OR(ISNA(MATCH(B2,Rutas!$A:$A,0)),ISNA(MATCH(C2,Conductores!$A:$A,0)),ISNA(MATCH(D2,Vehículos!$A:$A,0))),"REVISAR: ID no encontrado",IF(INDEX(Rutas!$C:$C,MATCH(B2,Rutas!$A:$A,0))<>INDEX(Vehículos!$B:$B,MATCH(D2,Vehículos!$A:$A,0)),"REVISAR: el vehículo no corresponde a la ruta",IF(INDEX(Rutas!$C:$C,MATCH(B2,Rutas!$A:$A,0))<>INDEX(Conductores!$D:$D,MATCH(C2,Conductores!$A:$A,0)),"REVISAR: el conductor no corresponde a la ruta",IF(OR(INDEX(Vehículos!$E:$E,MATCH(D2,Vehículos!$A:$A,0))="Taller",INDEX(Vehículos!$E:$E,MATCH(D2,Vehículos!$A:$A,0))="Fuera de servicio"),"REVISAR: vehículo no disponible",IF(INDEX(Conductores!$G:$G,MATCH(C2,Conductores!$A:$A,0))<>"Activo","REVISAR: conductor no activo",IF(COUNTIFS($A:$A,A2,$C:$C,C2)>1,"REVISAR: conductor asignado dos veces",IF(COUNTIFS($A:$A,A2,$D:$D,D2)>1,"REVISAR: vehículo asignado dos veces","OK")))))))) -> OK | H2: 24 | I2: 10 | J2: =IF(OR(H2="",H2=0),"",I2/H2) -> 0.41666667 | K2: En tiempo | M2: 0.4375 | O2: =IF(AND(OR(K2="En riesgo",K2="Atrasada"),L2=""),"Falta código de motivo",IF(AND(L2="OTR",N2=""),"Explica OTR en las notas",IF(AND(K2="Finalizada",I2<H2,L2=""),"Falta código de motivo",""))) | P2: =IF(OR(D2="",A2=""),"",IF(COUNTIFS(Revision_previa!$B:$B,D2,Revision_previa!$A:$A,">="&A2,Revision_previa!$A:$A,"<"&(A2+1))=0,"Sin revisión",IF(COUNTIFS(Revision_previa!$B:$B,D2,Revision_previa!$A:$A,">="&A2,Revision_previa!$A:$A,"<"&(A2+1),Revision_previa!$D:$D,"Falla")+COUNTIFS(Revision_previa!$B:$B,D2,Revision_previa!$A:$A,">="&A2,Revision_previa!$A:$A,"<"&(A2+1),Revision_previa!$E:$E,"Falla")+COUNTIFS(Revision_previa!$B:$B,D2,Revision_previa!$A:$A,">="&A2,Revision_previa!$A:$A,"<"&(A2+1),Revision_previa!$F:$F,"Falla")+COUNTIFS(Revision_previa!$B:$B,D2,Revision_previa!$A:$A,">="&A2,Revision_previa!$A:$A,"<"&(A2+1),Revision_previa!$H:$H,"Encendido")>0,"No apto","Apto"))) -> Apto
A3: 46304 | B3: BK-02 | C3: D02 | D3: V02 | E3: =IF(C3="","",IFERROR(INDEX(Conductores!$B:$B,MATCH(C3,Conductores!$A:$A,0)),"ID no encontrado")) -> Luis Almonte | F3: =IF(B3="","",IFERROR(INDEX(Rutas!$B:$B,MATCH(B3,Rutas!$A:$A,0)),"ID no encontrado")) -> Zona Colonial | G3: =IF(OR(B3="",C3="",D3=""),"",IF(OR(ISNA(MATCH(B3,Rutas!$A:$A,0)),ISNA(MATCH(C3,Conductores!$A:$A,0)),ISNA(MATCH(D3,Vehículos!$A:$A,0))),"REVISAR: ID no encontrado",IF(INDEX(Rutas!$C:$C,MATCH(B3,Rutas!$A:$A,0))<>INDEX(Vehículos!$B:$B,MATCH(D3,Vehículos!$A:$A,0)),"REVISAR: el vehículo no corresponde a la ruta",IF(INDEX(Rutas!$C:$C,MATCH(B3,Rutas!$A:$A,0))<>INDEX(Conductores!$D:$D,MATCH(C3,Conductores!$A:$A,0)),"REVISAR: el conductor no corresponde a la ruta",IF(OR(INDEX(Vehículos!$E:$E,MATCH(D3,Vehículos!$A:$A,0))="Taller",INDEX(Vehículos!$E:$E,MATCH(D3,Vehículos!$A:$A,0))="Fuera de servicio"),"REVISAR: vehículo no disponible",IF(INDEX(Conductores!$G:$G,MATCH(C3,Conductores!$A:$A,0))<>"Activo","REVISAR: conductor no activo",IF(COUNTIFS($A:$A,A3,$C:$C,C3)>1,"REVISAR: conductor asignado dos veces",IF(COUNTIFS($A:$A,A3,$D:$D,D3)>1,"REVISAR: vehículo asignado dos veces","OK")))))))) -> REVISAR: vehículo no disponible | H3: 22 | I3: 0 | J3: =IF(OR(H3="",H3=0),"",I3/H3) -> 0 | K3: No iniciada | N3: Ejemplo: el vehículo V02 está en el taller y la verificación lo señala | O3: =IF(AND(OR(K3="En riesgo",K3="Atrasada"),L3=""),"Falta código de motivo",IF(AND(L3="OTR",N3=""),"Explica OTR en las notas",IF(AND(K3="Finalizada",I3<H3,L3=""),"Falta código de motivo",""))) | P3: =IF(OR(D3="",A3=""),"",IF(COUNTIFS(Revision_previa!$B:$B,D3,Revision_previa!$A:$A,">="&A3,Revision_previa!$A:$A,"<"&(A3+1))=0,"Sin revisión",IF(COUNTIFS(Revision_previa!$B:$B,D3,Revision_previa!$A:$A,">="&A3,Revision_previa!$A:$A,"<"&(A3+1),Revision_previa!$D:$D,"Falla")+COUNTIFS(Revision_previa!$B:$B,D3,Revision_previa!$A:$A,">="&A3,Revision_previa!$A:$A,"<"&(A3+1),Revision_previa!$E:$E,"Falla")+COUNTIFS(Revision_previa!$B:$B,D3,Revision_previa!$A:$A,">="&A3,Revision_previa!$A:$A,"<"&(A3+1),Revision_previa!$F:$F,"Falla")+COUNTIFS(Revision_previa!$B:$B,D3,Revision_previa!$A:$A,">="&A3,Revision_previa!$A:$A,"<"&(A3+1),Revision_previa!$H:$H,"Encendido")>0,"No apto","Apto"))) -> Sin revisión
A4: 46304 | B4: TR-02 | C4: D21 | D4: V21 | E4: =IF(C4="","",IFERROR(INDEX(Conductores!$B:$B,MATCH(C4,Conductores!$A:$A,0)),"ID no encontrado")) -> Yeison Tavárez | F4: =IF(B4="","",IFERROR(INDEX(Rutas!$B:$B,MATCH(B4,Rutas!$A:$A,0)),"ID no encontrado")) -> Santiago | G4: =IF(OR(B4="",C4="",D4=""),"",IF(OR(ISNA(MATCH(B4,Rutas!$A:$A,0)),ISNA(MATCH(C4,Conductores!$A:$A,0)),ISNA(MATCH(D4,Vehículos!$A:$A,0))),"REVISAR: ID no encontrado",IF(INDEX(Rutas!$C:$C,MATCH(B4,Rutas!$A:$A,0))<>INDEX(Vehículos!$B:$B,MATCH(D4,Vehículos!$A:$A,0)),"REVISAR: el vehículo no corresponde a la ruta",IF(INDEX(Rutas!$C:$C,MATCH(B4,Rutas!$A:$A,0))<>INDEX(Conductores!$D:$D,MATCH(C4,Conductores!$A:$A,0)),"REVISAR: el conductor no corresponde a la ruta",IF(OR(INDEX(Vehículos!$E:$E,MATCH(D4,Vehículos!$A:$A,0))="Taller",INDEX(Vehículos!$E:$E,MATCH(D4,Vehículos!$A:$A,0))="Fuera de servicio"),"REVISAR: vehículo no disponible",IF(INDEX(Conductores!$G:$G,MATCH(C4,Conductores!$A:$A,0))<>"Activo","REVISAR: conductor no activo",IF(COUNTIFS($A:$A,A4,$C:$C,C4)>1,"REVISAR: conductor asignado dos veces",IF(COUNTIFS($A:$A,A4,$D:$D,D4)>1,"REVISAR: vehículo asignado dos veces","OK")))))))) -> OK | H4: 8 | I4: 3 | J4: =IF(OR(H4="",H4=0),"",I4/H4) -> 0.375 | K4: Atrasada | L4: TRA | M4: 0.48611111 | N4: Accidente en la autopista, 40 min detenido | O4: =IF(AND(OR(K4="En riesgo",K4="Atrasada"),L4=""),"Falta código de motivo",IF(AND(L4="OTR",N4=""),"Explica OTR en las notas",IF(AND(K4="Finalizada",I4<H4,L4=""),"Falta código de motivo",""))) | P4: =IF(OR(D4="",A4=""),"",IF(COUNTIFS(Revision_previa!$B:$B,D4,Revision_previa!$A:$A,">="&A4,Revision_previa!$A:$A,"<"&(A4+1))=0,"Sin revisión",IF(COUNTIFS(Revision_previa!$B:$B,D4,Revision_previa!$A:$A,">="&A4,Revision_previa!$A:$A,"<"&(A4+1),Revision_previa!$D:$D,"Falla")+COUNTIFS(Revision_previa!$B:$B,D4,Revision_previa!$A:$A,">="&A4,Revision_previa!$A:$A,"<"&(A4+1),Revision_previa!$E:$E,"Falla")+COUNTIFS(Revision_previa!$B:$B,D4,Revision_previa!$A:$A,">="&A4,Revision_previa!$A:$A,"<"&(A4+1),Revision_previa!$F:$F,"Falla")+COUNTIFS(Revision_previa!$B:$B,D4,Revision_previa!$A:$A,">="&A4,Revision_previa!$A:$A,"<"&(A4+1),Revision_previa!$H:$H,"Encendido")>0,"No apto","Apto"))) -> Apto
A5: 46304 | B5: VN-02 | C5: D15 | D5: V15 | E5: =IF(C5="","",IFERROR(INDEX(Conductores!$B:$B,MATCH(C5,Conductores!$A:$A,0)),"ID no encontrado")) -> Mercedes Rodríguez | F5: =IF(B5="","",IFERROR(INDEX(Rutas!$B:$B,MATCH(B5,Rutas!$A:$A,0)),"ID no encontrado")) -> San Cristóbal | G5: =IF(OR(B5="",C5="",D5=""),"",IF(OR(ISNA(MATCH(B5,Rutas!$A:$A,0)),ISNA(MATCH(C5,Conductores!$A:$A,0)),ISNA(MATCH(D5,Vehículos!$A:$A,0))),"REVISAR: ID no encontrado",IF(INDEX(Rutas!$C:$C,MATCH(B5,Rutas!$A:$A,0))<>INDEX(Vehículos!$B:$B,MATCH(D5,Vehículos!$A:$A,0)),"REVISAR: el vehículo no corresponde a la ruta",IF(INDEX(Rutas!$C:$C,MATCH(B5,Rutas!$A:$A,0))<>INDEX(Conductores!$D:$D,MATCH(C5,Conductores!$A:$A,0)),"REVISAR: el conductor no corresponde a la ruta",IF(OR(INDEX(Vehículos!$E:$E,MATCH(D5,Vehículos!$A:$A,0))="Taller",INDEX(Vehículos!$E:$E,MATCH(D5,Vehículos!$A:$A,0))="Fuera de servicio"),"REVISAR: vehículo no disponible",IF(INDEX(Conductores!$G:$G,MATCH(C5,Conductores!$A:$A,0))<>"Activo","REVISAR: conductor no activo",IF(COUNTIFS($A:$A,A5,$C:$C,C5)>1,"REVISAR: conductor asignado dos veces",IF(COUNTIFS($A:$A,A5,$D:$D,D5)>1,"REVISAR: vehículo asignado dos veces","OK")))))))) -> OK | H5: 18 | I5: 9 | J5: =IF(OR(H5="",H5=0),"",I5/H5) -> 0.5 | K5: En riesgo | M5: 0.46875 | N5: Ejemplo: falta el código de motivo y la verificación lo señala | O5: =IF(AND(OR(K5="En riesgo",K5="Atrasada"),L5=""),"Falta código de motivo",IF(AND(L5="OTR",N5=""),"Explica OTR en las notas",IF(AND(K5="Finalizada",I5<H5,L5=""),"Falta código de motivo",""))) -> Falta código de motivo | P5: =IF(OR(D5="",A5=""),"",IF(COUNTIFS(Revision_previa!$B:$B,D5,Revision_previa!$A:$A,">="&A5,Revision_previa!$A:$A,"<"&(A5+1))=0,"Sin revisión",IF(COUNTIFS(Revision_previa!$B:$B,D5,Revision_previa!$A:$A,">="&A5,Revision_previa!$A:$A,"<"&(A5+1),Revision_previa!$D:$D,"Falla")+COUNTIFS(Revision_previa!$B:$B,D5,Revision_previa!$A:$A,">="&A5,Revision_previa!$A:$A,"<"&(A5+1),Revision_previa!$E:$E,"Falla")+COUNTIFS(Revision_previa!$B:$B,D5,Revision_previa!$A:$A,">="&A5,Revision_previa!$A:$A,"<"&(A5+1),Revision_previa!$F:$F,"Falla")+COUNTIFS(Revision_previa!$B:$B,D5,Revision_previa!$A:$A,">="&A5,Revision_previa!$A:$A,"<"&(A5+1),Revision_previa!$H:$H,"Encendido")>0,"No apto","Apto"))) -> No apto
E6: =IF(C6="","",IFERROR(INDEX(Conductores!$B:$B,MATCH(C6,Conductores!$A:$A,0)),"ID no encontrado")) | F6: =IF(B6="","",IFERROR(INDEX(Rutas!$B:$B,MATCH(B6,Rutas!$A:$A,0)),"ID no encontrado")) | G6: =IF(OR(B6="",C6="",D6=""),"",IF(OR(ISNA(MATCH(B6,Rutas!$A:$A,0)),ISNA(MATCH(C6,Conductores!$A:$A,0)),ISNA(MATCH(D6,Vehículos!$A:$A,0))),"REVISAR: ID no encontrado",IF(INDEX(Rutas!$C:$C,MATCH(B6,Rutas!$A:$A,0))<>INDEX(Vehículos!$B:$B,MATCH(D6,Vehículos!$A:$A,0)),"REVISAR: el vehículo no corresponde a la ruta",IF(INDEX(Rutas!$C:$C,MATCH(B6,Rutas!$A:$A,0))<>INDEX(Conductores!$D:$D,MATCH(C6,Conductores!$A:$A,0)),"REVISAR: el conductor no corresponde a la ruta",IF(OR(INDEX(Vehículos!$E:$E,MATCH(D6,Vehículos!$A:$A,0))="Taller",INDEX(Vehículos!$E:$E,MATCH(D6,Vehículos!$A:$A,0))="Fuera de servicio"),"REVISAR: vehículo no disponible",IF(INDEX(Conductores!$G:$G,MATCH(C6,Conductores!$A:$A,0))<>"Activo","REVISAR: conductor no activo",IF(COUNTIFS($A:$A,A6,$C:$C,C6)>1,"REVISAR: conductor asignado dos veces",IF(COUNTIFS($A:$A,A6,$D:$D,D6)>1,"REVISAR: vehículo asignado dos veces","OK")))))))) | J6: =IF(OR(H6="",H6=0),"",I6/H6) | O6: =IF(AND(OR(K6="En riesgo",K6="Atrasada"),L6=""),"Falta código de motivo",IF(AND(L6="OTR",N6=""),"Explica OTR en las notas",IF(AND(K6="Finalizada",I6<H6,L6=""),"Falta código de motivo",""))) | P6: =IF(OR(D6="",A6=""),"",IF(COUNTIFS(Revision_previa!$B:$B,D6,Revision_previa!$A:$A,">="&A6,Revision_previa!$A:$A,"<"&(A6+1))=0,"Sin revisión",IF(COUNTIFS(Revision_previa!$B:$B,D6,Revision_previa!$A:$A,">="&A6,Revision_previa!$A:$A,"<"&(A6+1),Revision_previa!$D:$D,"Falla")+COUNTIFS(Revision_previa!$B:$B,D6,Revision_previa!$A:$A,">="&A6,Revision_previa!$A:$A,"<"&(A6+1),Revision_previa!$E:$E,"Falla")+COUNTIFS(Revision_previa!$B:$B,D6,Revision_previa!$A:$A,">="&A6,Revision_previa!$A:$A,"<"&(A6+1),Revision_previa!$F:$F,"Falla")+COUNTIFS(Revision_previa!$B:$B,D6,Revision_previa!$A:$A,">="&A6,Revision_previa!$A:$A,"<"&(A6+1),Revision_previa!$H:$H,"Encendido")>0,"No apto","Apto")))
E7: =IF(C7="","",IFERROR(INDEX(Conductores!$B:$B,MATCH(C7,Conductores!$A:$A,0)),"ID no encontrado")) | F7: =IF(B7="","",IFERROR(INDEX(Rutas!$B:$B,MATCH(B7,Rutas!$A:$A,0)),"ID no encontrado")) | G7: =IF(OR(B7="",C7="",D7=""),"",IF(OR(ISNA(MATCH(B7,Rutas!$A:$A,0)),ISNA(MATCH(C7,Conductores!$A:$A,0)),ISNA(MATCH(D7,Vehículos!$A:$A,0))),"REVISAR: ID no encontrado",IF(INDEX(Rutas!$C:$C,MATCH(B7,Rutas!$A:$A,0))<>INDEX(Vehículos!$B:$B,MATCH(D7,Vehículos!$A:$A,0)),"REVISAR: el vehículo no corresponde a la ruta",IF(INDEX(Rutas!$C:$C,MATCH(B7,Rutas!$A:$A,0))<>INDEX(Conductores!$D:$D,MATCH(C7,Conductores!$A:$A,0)),"REVISAR: el conductor no corresponde a la ruta",IF(OR(INDEX(Vehículos!$E:$E,MATCH(D7,Vehículos!$A:$A,0))="Taller",INDEX(Vehículos!$E:$E,MATCH(D7,Vehículos!$A:$A,0))="Fuera de servicio"),"REVISAR: vehículo no disponible",IF(INDEX(Conductores!$G:$G,MATCH(C7,Conductores!$A:$A,0))<>"Activo","REVISAR: conductor no activo",IF(COUNTIFS($A:$A,A7,$C:$C,C7)>1,"REVISAR: conductor asignado dos veces",IF(COUNTIFS($A:$A,A7,$D:$D,D7)>1,"REVISAR: vehículo asignado dos veces","OK")))))))) | J7: =IF(OR(H7="",H7=0),"",I7/H7) | O7: =IF(AND(OR(K7="En riesgo",K7="Atrasada"),L7=""),"Falta código de motivo",IF(AND(L7="OTR",N7=""),"Explica OTR en las notas",IF(AND(K7="Finalizada",I7<H7,L7=""),"Falta código de motivo",""))) | P7: =IF(OR(D7="",A7=""),"",IF(COUNTIFS(Revision_previa!$B:$B,D7,Revision_previa!$A:$A,">="&A7,Revision_previa!$A:$A,"<"&(A7+1))=0,"Sin revisión",IF(COUNTIFS(Revision_previa!$B:$B,D7,Revision_previa!$A:$A,">="&A7,Revision_previa!$A:$A,"<"&(A7+1),Revision_previa!$D:$D,"Falla")+COUNTIFS(Revision_previa!$B:$B,D7,Revision_previa!$A:$A,">="&A7,Revision_previa!$A:$A,"<"&(A7+1),Revision_previa!$E:$E,"Falla")+COUNTIFS(Revision_previa!$B:$B,D7,Revision_previa!$A:$A,">="&A7,Revision_previa!$A:$A,"<"&(A7+1),Revision_previa!$F:$F,"Falla")+COUNTIFS(Revision_previa!$B:$B,D7,Revision_previa!$A:$A,">="&A7,Revision_previa!$A:$A,"<"&(A7+1),Revision_previa!$H:$H,"Encendido")>0,"No apto","Apto")))
E8: =IF(C8="","",IFERROR(INDEX(Conductores!$B:$B,MATCH(C8,Conductores!$A:$A,0)),"ID no encontrado")) | F8: =IF(B8="","",IFERROR(INDEX(Rutas!$B:$B,MATCH(B8,Rutas!$A:$A,0)),"ID no encontrado")) | G8: =IF(OR(B8="",C8="",D8=""),"",IF(OR(ISNA(MATCH(B8,Rutas!$A:$A,0)),ISNA(MATCH(C8,Conductores!$A:$A,0)),ISNA(MATCH(D8,Vehículos!$A:$A,0))),"REVISAR: ID no encontrado",IF(INDEX(Rutas!$C:$C,MATCH(B8,Rutas!$A:$A,0))<>INDEX(Vehículos!$B:$B,MATCH(D8,Vehículos!$A:$A,0)),"REVISAR: el vehículo no corresponde a la ruta",IF(INDEX(Rutas!$C:$C,MATCH(B8,Rutas!$A:$A,0))<>INDEX(Conductores!$D:$D,MATCH(C8,Conductores!$A:$A,0)),"REVISAR: el conductor no corresponde a la ruta",IF(OR(INDEX(Vehículos!$E:$E,MATCH(D8,Vehículos!$A:$A,0))="Taller",INDEX(Vehículos!$E:$E,MATCH(D8,Vehículos!$A:$A,0))="Fuera de servicio"),"REVISAR: vehículo no disponible",IF(INDEX(Conductores!$G:$G,MATCH(C8,Conductores!$A:$A,0))<>"Activo","REVISAR: conductor no activo",IF(COUNTIFS($A:$A,A8,$C:$C,C8)>1,"REVISAR: conductor asignado dos veces",IF(COUNTIFS($A:$A,A8,$D:$D,D8)>1,"REVISAR: vehículo asignado dos veces","OK")))))))) | J8: =IF(OR(H8="",H8=0),"",I8/H8) | O8: =IF(AND(OR(K8="En riesgo",K8="Atrasada"),L8=""),"Falta código de motivo",IF(AND(L8="OTR",N8=""),"Explica OTR en las notas",IF(AND(K8="Finalizada",I8<H8,L8=""),"Falta código de motivo",""))) | P8: =IF(OR(D8="",A8=""),"",IF(COUNTIFS(Revision_previa!$B:$B,D8,Revision_previa!$A:$A,">="&A8,Revision_previa!$A:$A,"<"&(A8+1))=0,"Sin revisión",IF(COUNTIFS(Revision_previa!$B:$B,D8,Revision_previa!$A:$A,">="&A8,Revision_previa!$A:$A,"<"&(A8+1),Revision_previa!$D:$D,"Falla")+COUNTIFS(Revision_previa!$B:$B,D8,Revision_previa!$A:$A,">="&A8,Revision_previa!$A:$A,"<"&(A8+1),Revision_previa!$E:$E,"Falla")+COUNTIFS(Revision_previa!$B:$B,D8,Revision_previa!$A:$A,">="&A8,Revision_previa!$A:$A,"<"&(A8+1),Revision_previa!$F:$F,"Falla")+COUNTIFS(Revision_previa!$B:$B,D8,Revision_previa!$A:$A,">="&A8,Revision_previa!$A:$A,"<"&(A8+1),Revision_previa!$H:$H,"Encendido")>0,"No apto","Apto")))
E9: =IF(C9="","",IFERROR(INDEX(Conductores!$B:$B,MATCH(C9,Conductores!$A:$A,0)),"ID no encontrado")) | F9: =IF(B9="","",IFERROR(INDEX(Rutas!$B:$B,MATCH(B9,Rutas!$A:$A,0)),"ID no encontrado")) | G9: =IF(OR(B9="",C9="",D9=""),"",IF(OR(ISNA(MATCH(B9,Rutas!$A:$A,0)),ISNA(MATCH(C9,Conductores!$A:$A,0)),ISNA(MATCH(D9,Vehículos!$A:$A,0))),"REVISAR: ID no encontrado",IF(INDEX(Rutas!$C:$C,MATCH(B9,Rutas!$A:$A,0))<>INDEX(Vehículos!$B:$B,MATCH(D9,Vehículos!$A:$A,0)),"REVISAR: el vehículo no corresponde a la ruta",IF(INDEX(Rutas!$C:$C,MATCH(B9,Rutas!$A:$A,0))<>INDEX(Conductores!$D:$D,MATCH(C9,Conductores!$A:$A,0)),"REVISAR: el conductor no corresponde a la ruta",IF(OR(INDEX(Vehículos!$E:$E,MATCH(D9,Vehículos!$A:$A,0))="Taller",INDEX(Vehículos!$E:$E,MATCH(D9,Vehículos!$A:$A,0))="Fuera de servicio"),"REVISAR: vehículo no disponible",IF(INDEX(Conductores!$G:$G,MATCH(C9,Conductores!$A:$A,0))<>"Activo","REVISAR: conductor no activo",IF(COUNTIFS($A:$A,A9,$C:$C,C9)>1,"REVISAR: conductor asignado dos veces",IF(COUNTIFS($A:$A,A9,$D:$D,D9)>1,"REVISAR: vehículo asignado dos veces","OK")))))))) | J9: =IF(OR(H9="",H9=0),"",I9/H9) | O9: =IF(AND(OR(K9="En riesgo",K9="Atrasada"),L9=""),"Falta código de motivo",IF(AND(L9="OTR",N9=""),"Explica OTR en las notas",IF(AND(K9="Finalizada",I9<H9,L9=""),"Falta código de motivo",""))) | P9: =IF(OR(D9="",A9=""),"",IF(COUNTIFS(Revision_previa!$B:$B,D9,Revision_previa!$A:$A,">="&A9,Revision_previa!$A:$A,"<"&(A9+1))=0,"Sin revisión",IF(COUNTIFS(Revision_previa!$B:$B,D9,Revision_previa!$A:$A,">="&A9,Revision_previa!$A:$A,"<"&(A9+1),Revision_previa!$D:$D,"Falla")+COUNTIFS(Revision_previa!$B:$B,D9,Revision_previa!$A:$A,">="&A9,Revision_previa!$A:$A,"<"&(A9+1),Revision_previa!$E:$E,"Falla")+COUNTIFS(Revision_previa!$B:$B,D9,Revision_previa!$A:$A,">="&A9,Revision_previa!$A:$A,"<"&(A9+1),Revision_previa!$F:$F,"Falla")+COUNTIFS(Revision_previa!$B:$B,D9,Revision_previa!$A:$A,">="&A9,Revision_previa!$A:$A,"<"&(A9+1),Revision_previa!$H:$H,"Encendido")>0,"No apto","Apto")))
E10: =IF(C10="","",IFERROR(INDEX(Conductores!$B:$B,MATCH(C10,Conductores!$A:$A,0)),"ID no encontrado")) | F10: =IF(B10="","",IFERROR(INDEX(Rutas!$B:$B,MATCH(B10,Rutas!$A:$A,0)),"ID no encontrado")) | G10: =IF(OR(B10="",C10="",D10=""),"",IF(OR(ISNA(MATCH(B10,Rutas!$A:$A,0)),ISNA(MATCH(C10,Conductores!$A:$A,0)),ISNA(MATCH(D10,Vehículos!$A:$A,0))),"REVISAR: ID no encontrado",IF(INDEX(Rutas!$C:$C,MATCH(B10,Rutas!$A:$A,0))<>INDEX(Vehículos!$B:$B,MATCH(D10,Vehículos!$A:$A,0)),"REVISAR: el vehículo no corresponde a la ruta",IF(INDEX(Rutas!$C:$C,MATCH(B10,Rutas!$A:$A,0))<>INDEX(Conductores!$D:$D,MATCH(C10,Conductores!$A:$A,0)),"REVISAR: el conductor no corresponde a la ruta",IF(OR(INDEX(Vehículos!$E:$E,MATCH(D10,Vehículos!$A:$A,0))="Taller",INDEX(Vehículos!$E:$E,MATCH(D10,Vehículos!$A:$A,0))="Fuera de servicio"),"REVISAR: vehículo no disponible",IF(INDEX(Conductores!$G:$G,MATCH(C10,Conductores!$A:$A,0))<>"Activo","REVISAR: conductor no activo",IF(COUNTIFS($A:$A,A10,$C:$C,C10)>1,"REVISAR: conductor asignado dos veces",IF(COUNTIFS($A:$A,A10,$D:$D,D10)>1,"REVISAR: vehículo asignado dos veces","OK")))))))) | J10: =IF(OR(H10="",H10=0),"",I10/H10) | O10: =IF(AND(OR(K10="En riesgo",K10="Atrasada"),L10=""),"Falta código de motivo",IF(AND(L10="OTR",N10=""),"Explica OTR en las notas",IF(AND(K10="Finalizada",I10<H10,L10=""),"Falta código de motivo",""))) | P10: =IF(OR(D10="",A10=""),"",IF(COUNTIFS(Revision_previa!$B:$B,D10,Revision_previa!$A:$A,">="&A10,Revision_previa!$A:$A,"<"&(A10+1))=0,"Sin revisión",IF(COUNTIFS(Revision_previa!$B:$B,D10,Revision_previa!$A:$A,">="&A10,Revision_previa!$A:$A,"<"&(A10+1),Revision_previa!$D:$D,"Falla")+COUNTIFS(Revision_previa!$B:$B,D10,Revision_previa!$A:$A,">="&A10,Revision_previa!$A:$A,"<"&(A10+1),Revision_previa!$E:$E,"Falla")+COUNTIFS(Revision_previa!$B:$B,D10,Revision_previa!$A:$A,">="&A10,Revision_previa!$A:$A,"<"&(A10+1),Revision_previa!$F:$F,"Falla")+COUNTIFS(Revision_previa!$B:$B,D10,Revision_previa!$A:$A,">="&A10,Revision_previa!$A:$A,"<"&(A10+1),Revision_previa!$H:$H,"Encendido")>0,"No apto","Apto")))
E11: =IF(C11="","",IFERROR(INDEX(Conductores!$B:$B,MATCH(C11,Conductores!$A:$A,0)),"ID no encontrado")) | F11: =IF(B11="","",IFERROR(INDEX(Rutas!$B:$B,MATCH(B11,Rutas!$A:$A,0)),"ID no encontrado")) | G11: =IF(OR(B11="",C11="",D11=""),"",IF(OR(ISNA(MATCH(B11,Rutas!$A:$A,0)),ISNA(MATCH(C11,Conductores!$A:$A,0)),ISNA(MATCH(D11,Vehículos!$A:$A,0))),"REVISAR: ID no encontrado",IF(INDEX(Rutas!$C:$C,MATCH(B11,Rutas!$A:$A,0))<>INDEX(Vehículos!$B:$B,MATCH(D11,Vehículos!$A:$A,0)),"REVISAR: el vehículo no corresponde a la ruta",IF(INDEX(Rutas!$C:$C,MATCH(B11,Rutas!$A:$A,0))<>INDEX(Conductores!$D:$D,MATCH(C11,Conductores!$A:$A,0)),"REVISAR: el conductor no corresponde a la ruta",IF(OR(INDEX(Vehículos!$E:$E,MATCH(D11,Vehículos!$A:$A,0))="Taller",INDEX(Vehículos!$E:$E,MATCH(D11,Vehículos!$A:$A,0))="Fuera de servicio"),"REVISAR: vehículo no disponible",IF(INDEX(Conductores!$G:$G,MATCH(C11,Conductores!$A:$A,0))<>"Activo","REVISAR: conductor no activo",IF(COUNTIFS($A:$A,A11,$C:$C,C11)>1,"REVISAR: conductor asignado dos veces",IF(COUNTIFS($A:$A,A11,$D:$D,D11)>1,"REVISAR: vehículo asignado dos veces","OK")))))))) | J11: =IF(OR(H11="",H11=0),"",I11/H11) | O11: =IF(AND(OR(K11="En riesgo",K11="Atrasada"),L11=""),"Falta código de motivo",IF(AND(L11="OTR",N11=""),"Explica OTR en las notas",IF(AND(K11="Finalizada",I11<H11,L11=""),"Falta código de motivo",""))) | P11: =IF(OR(D11="",A11=""),"",IF(COUNTIFS(Revision_previa!$B:$B,D11,Revision_previa!$A:$A,">="&A11,Revision_previa!$A:$A,"<"&(A11+1))=0,"Sin revisión",IF(COUNTIFS(Revision_previa!$B:$B,D11,Revision_previa!$A:$A,">="&A11,Revision_previa!$A:$A,"<"&(A11+1),Revision_previa!$D:$D,"Falla")+COUNTIFS(Revision_previa!$B:$B,D11,Revision_previa!$A:$A,">="&A11,Revision_previa!$A:$A,"<"&(A11+1),Revision_previa!$E:$E,"Falla")+COUNTIFS(Revision_previa!$B:$B,D11,Revision_previa!$A:$A,">="&A11,Revision_previa!$A:$A,"<"&(A11+1),Revision_previa!$F:$F,"Falla")+COUNTIFS(Revision_previa!$B:$B,D11,Revision_previa!$A:$A,">="&A11,Revision_previa!$A:$A,"<"&(A11+1),Revision_previa!$H:$H,"Encendido")>0,"No apto","Apto")))
E12: =IF(C12="","",IFERROR(INDEX(Conductores!$B:$B,MATCH(C12,Conductores!$A:$A,0)),"ID no encontrado")) | F12: =IF(B12="","",IFERROR(INDEX(Rutas!$B:$B,MATCH(B12,Rutas!$A:$A,0)),"ID no encontrado")) | G12: =IF(OR(B12="",C12="",D12=""),"",IF(OR(ISNA(MATCH(B12,Rutas!$A:$A,0)),ISNA(MATCH(C12,Conductores!$A:$A,0)),ISNA(MATCH(D12,Vehículos!$A:$A,0))),"REVISAR: ID no encontrado",IF(INDEX(Rutas!$C:$C,MATCH(B12,Rutas!$A:$A,0))<>INDEX(Vehículos!$B:$B,MATCH(D12,Vehículos!$A:$A,0)),"REVISAR: el vehículo no corresponde a la ruta",IF(INDEX(Rutas!$C:$C,MATCH(B12,Rutas!$A:$A,0))<>INDEX(Conductores!$D:$D,MATCH(C12,Conductores!$A:$A,0)),"REVISAR: el conductor no corresponde a la ruta",IF(OR(INDEX(Vehículos!$E:$E,MATCH(D12,Vehículos!$A:$A,0))="Taller",INDEX(Vehículos!$E:$E,MATCH(D12,Vehículos!$A:$A,0))="Fuera de servicio"),"REVISAR: vehículo no disponible",IF(INDEX(Conductores!$G:$G,MATCH(C12,Conductores!$A:$A,0))<>"Activo","REVISAR: conductor no activo",IF(COUNTIFS($A:$A,A12,$C:$C,C12)>1,"REVISAR: conductor asignado dos veces",IF(COUNTIFS($A:$A,A12,$D:$D,D12)>1,"REVISAR: vehículo asignado dos veces","OK")))))))) | J12: =IF(OR(H12="",H12=0),"",I12/H12) | O12: =IF(AND(OR(K12="En riesgo",K12="Atrasada"),L12=""),"Falta código de motivo",IF(AND(L12="OTR",N12=""),"Explica OTR en las notas",IF(AND(K12="Finalizada",I12<H12,L12=""),"Falta código de motivo",""))) | P12: =IF(OR(D12="",A12=""),"",IF(COUNTIFS(Revision_previa!$B:$B,D12,Revision_previa!$A:$A,">="&A12,Revision_previa!$A:$A,"<"&(A12+1))=0,"Sin revisión",IF(COUNTIFS(Revision_previa!$B:$B,D12,Revision_previa!$A:$A,">="&A12,Revision_previa!$A:$A,"<"&(A12+1),Revision_previa!$D:$D,"Falla")+COUNTIFS(Revision_previa!$B:$B,D12,Revision_previa!$A:$A,">="&A12,Revision_previa!$A:$A,"<"&(A12+1),Revision_previa!$E:$E,"Falla")+COUNTIFS(Revision_previa!$B:$B,D12,Revision_previa!$A:$A,">="&A12,Revision_previa!$A:$A,"<"&(A12+1),Revision_previa!$F:$F,"Falla")+COUNTIFS(Revision_previa!$B:$B,D12,Revision_previa!$A:$A,">="&A12,Revision_previa!$A:$A,"<"&(A12+1),Revision_previa!$H:$H,"Encendido")>0,"No apto","Apto")))
E13: =IF(C13="","",IFERROR(INDEX(Conductores!$B:$B,MATCH(C13,Conductores!$A:$A,0)),"ID no encontrado")) | F13: =IF(B13="","",IFERROR(INDEX(Rutas!$B:$B,MATCH(B13,Rutas!$A:$A,0)),"ID no encontrado")) | G13: =IF(OR(B13="",C13="",D13=""),"",IF(OR(ISNA(MATCH(B13,Rutas!$A:$A,0)),ISNA(MATCH(C13,Conductores!$A:$A,0)),ISNA(MATCH(D13,Vehículos!$A:$A,0))),"REVISAR: ID no encontrado",IF(INDEX(Rutas!$C:$C,MATCH(B13,Rutas!$A:$A,0))<>INDEX(Vehículos!$B:$B,MATCH(D13,Vehículos!$A:$A,0)),"REVISAR: el vehículo no corresponde a la ruta",IF(INDEX(Rutas!$C:$C,MATCH(B13,Rutas!$A:$A,0))<>INDEX(Conductores!$D:$D,MATCH(C13,Conductores!$A:$A,0)),"REVISAR: el conductor no corresponde a la ruta",IF(OR(INDEX(Vehículos!$E:$E,MATCH(D13,Vehículos!$A:$A,0))="Taller",INDEX(Vehículos!$E:$E,MATCH(D13,Vehículos!$A:$A,0))="Fuera de servicio"),"REVISAR: vehículo no disponible",IF(INDEX(Conductores!$G:$G,MATCH(C13,Conductores!$A:$A,0))<>"Activo","REVISAR: conductor no activo",IF(COUNTIFS($A:$A,A13,$C:$C,C13)>1,"REVISAR: conductor asignado dos veces",IF(COUNTIFS($A:$A,A13,$D:$D,D13)>1,"REVISAR: vehículo asignado dos veces","OK")))))))) | J13: =IF(OR(H13="",H13=0),"",I13/H13) | O13: =IF(AND(OR(K13="En riesgo",K13="Atrasada"),L13=""),"Falta código de motivo",IF(AND(L13="OTR",N13=""),"Explica OTR en las notas",IF(AND(K13="Finalizada",I13<H13,L13=""),"Falta código de motivo",""))) | P13: =IF(OR(D13="",A13=""),"",IF(COUNTIFS(Revision_previa!$B:$B,D13,Revision_previa!$A:$A,">="&A13,Revision_previa!$A:$A,"<"&(A13+1))=0,"Sin revisión",IF(COUNTIFS(Revision_previa!$B:$B,D13,Revision_previa!$A:$A,">="&A13,Revision_previa!$A:$A,"<"&(A13+1),Revision_previa!$D:$D,"Falla")+COUNTIFS(Revision_previa!$B:$B,D13,Revision_previa!$A:$A,">="&A13,Revision_previa!$A:$A,"<"&(A13+1),Revision_previa!$E:$E,"Falla")+COUNTIFS(Revision_previa!$B:$B,D13,Revision_previa!$A:$A,">="&A13,Revision_previa!$A:$A,"<"&(A13+1),Revision_previa!$F:$F,"Falla")+COUNTIFS(Revision_previa!$B:$B,D13,Revision_previa!$A:$A,">="&A13,Revision_previa!$A:$A,"<"&(A13+1),Revision_previa!$H:$H,"Encendido")>0,"No apto","Apto")))
E14: =IF(C14="","",IFERROR(INDEX(Conductores!$B:$B,MATCH(C14,Conductores!$A:$A,0)),"ID no encontrado")) | F14: =IF(B14="","",IFERROR(INDEX(Rutas!$B:$B,MATCH(B14,Rutas!$A:$A,0)),"ID no encontrado")) | G14: =IF(OR(B14="",C14="",D14=""),"",IF(OR(ISNA(MATCH(B14,Rutas!$A:$A,0)),ISNA(MATCH(C14,Conductores!$A:$A,0)),ISNA(MATCH(D14,Vehículos!$A:$A,0))),"REVISAR: ID no encontrado",IF(INDEX(Rutas!$C:$C,MATCH(B14,Rutas!$A:$A,0))<>INDEX(Vehículos!$B:$B,MATCH(D14,Vehículos!$A:$A,0)),"REVISAR: el vehículo no corresponde a la ruta",IF(INDEX(Rutas!$C:$C,MATCH(B14,Rutas!$A:$A,0))<>INDEX(Conductores!$D:$D,MATCH(C14,Conductores!$A:$A,0)),"REVISAR: el conductor no corresponde a la ruta",IF(OR(INDEX(Vehículos!$E:$E,MATCH(D14,Vehículos!$A:$A,0))="Taller",INDEX(Vehículos!$E:$E,MATCH(D14,Vehículos!$A:$A,0))="Fuera de servicio"),"REVISAR: vehículo no disponible",IF(INDEX(Conductores!$G:$G,MATCH(C14,Conductores!$A:$A,0))<>"Activo","REVISAR: conductor no activo",IF(COUNTIFS($A:$A,A14,$C:$C,C14)>1,"REVISAR: conductor asignado dos veces",IF(COUNTIFS($A:$A,A14,$D:$D,D14)>1,"REVISAR: vehículo asignado dos veces","OK")))))))) | J14: =IF(OR(H14="",H14=0),"",I14/H14) | O14: =IF(AND(OR(K14="En riesgo",K14="Atrasada"),L14=""),"Falta código de motivo",IF(AND(L14="OTR",N14=""),"Explica OTR en las notas",IF(AND(K14="Finalizada",I14<H14,L14=""),"Falta código de motivo",""))) | P14: =IF(OR(D14="",A14=""),"",IF(COUNTIFS(Revision_previa!$B:$B,D14,Revision_previa!$A:$A,">="&A14,Revision_previa!$A:$A,"<"&(A14+1))=0,"Sin revisión",IF(COUNTIFS(Revision_previa!$B:$B,D14,Revision_previa!$A:$A,">="&A14,Revision_previa!$A:$A,"<"&(A14+1),Revision_previa!$D:$D,"Falla")+COUNTIFS(Revision_previa!$B:$B,D14,Revision_previa!$A:$A,">="&A14,Revision_previa!$A:$A,"<"&(A14+1),Revision_previa!$E:$E,"Falla")+COUNTIFS(Revision_previa!$B:$B,D14,Revision_previa!$A:$A,">="&A14,Revision_previa!$A:$A,"<"&(A14+1),Revision_previa!$F:$F,"Falla")+COUNTIFS(Revision_previa!$B:$B,D14,Revision_previa!$A:$A,">="&A14,Revision_previa!$A:$A,"<"&(A14+1),Revision_previa!$H:$H,"Encendido")>0,"No apto","Apto")))
E15: =IF(C15="","",IFERROR(INDEX(Conductores!$B:$B,MATCH(C15,Conductores!$A:$A,0)),"ID no encontrado")) | F15: =IF(B15="","",IFERROR(INDEX(Rutas!$B:$B,MATCH(B15,Rutas!$A:$A,0)),"ID no encontrado")) | G15: =IF(OR(B15="",C15="",D15=""),"",IF(OR(ISNA(MATCH(B15,Rutas!$A:$A,0)),ISNA(MATCH(C15,Conductores!$A:$A,0)),ISNA(MATCH(D15,Vehículos!$A:$A,0))),"REVISAR: ID no encontrado",IF(INDEX(Rutas!$C:$C,MATCH(B15,Rutas!$A:$A,0))<>INDEX(Vehículos!$B:$B,MATCH(D15,Vehículos!$A:$A,0)),"REVISAR: el vehículo no corresponde a la ruta",IF(INDEX(Rutas!$C:$C,MATCH(B15,Rutas!$A:$A,0))<>INDEX(Conductores!$D:$D,MATCH(C15,Conductores!$A:$A,0)),"REVISAR: el conductor no corresponde a la ruta",IF(OR(INDEX(Vehículos!$E:$E,MATCH(D15,Vehículos!$A:$A,0))="Taller",INDEX(Vehículos!$E:$E,MATCH(D15,Vehículos!$A:$A,0))="Fuera de servicio"),"REVISAR: vehículo no disponible",IF(INDEX(Conductores!$G:$G,MATCH(C15,Conductores!$A:$A,0))<>"Activo","REVISAR: conductor no activo",IF(COUNTIFS($A:$A,A15,$C:$C,C15)>1,"REVISAR: conductor asignado dos veces",IF(COUNTIFS($A:$A,A15,$D:$D,D15)>1,"REVISAR: vehículo asignado dos veces","OK")))))))) | J15: =IF(OR(H15="",H15=0),"",I15/H15) | O15: =IF(AND(OR(K15="En riesgo",K15="Atrasada"),L15=""),"Falta código de motivo",IF(AND(L15="OTR",N15=""),"Explica OTR en las notas",IF(AND(K15="Finalizada",I15<H15,L15=""),"Falta código de motivo",""))) | P15: =IF(OR(D15="",A15=""),"",IF(COUNTIFS(Revision_previa!$B:$B,D15,Revision_previa!$A:$A,">="&A15,Revision_previa!$A:$A,"<"&(A15+1))=0,"Sin revisión",IF(COUNTIFS(Revision_previa!$B:$B,D15,Revision_previa!$A:$A,">="&A15,Revision_previa!$A:$A,"<"&(A15+1),Revision_previa!$D:$D,"Falla")+COUNTIFS(Revision_previa!$B:$B,D15,Revision_previa!$A:$A,">="&A15,Revision_previa!$A:$A,"<"&(A15+1),Revision_previa!$E:$E,"Falla")+COUNTIFS(Revision_previa!$B:$B,D15,Revision_previa!$A:$A,">="&A15,Revision_previa!$A:$A,"<"&(A15+1),Revision_previa!$F:$F,"Falla")+COUNTIFS(Revision_previa!$B:$B,D15,Revision_previa!$A:$A,">="&A15,Revision_previa!$A:$A,"<"&(A15+1),Revision_previa!$H:$H,"Encendido")>0,"No apto","Apto")))
E16: =IF(C16="","",IFERROR(INDEX(Conductores!$B:$B,MATCH(C16,Conductores!$A:$A,0)),"ID no encontrado")) | F16: =IF(B16="","",IFERROR(INDEX(Rutas!$B:$B,MATCH(B16,Rutas!$A:$A,0)),"ID no encontrado")) | G16: =IF(OR(B16="",C16="",D16=""),"",IF(OR(ISNA(MATCH(B16,Rutas!$A:$A,0)),ISNA(MATCH(C16,Conductores!$A:$A,0)),ISNA(MATCH(D16,Vehículos!$A:$A,0))),"REVISAR: ID no encontrado",IF(INDEX(Rutas!$C:$C,MATCH(B16,Rutas!$A:$A,0))<>INDEX(Vehículos!$B:$B,MATCH(D16,Vehículos!$A:$A,0)),"REVISAR: el vehículo no corresponde a la ruta",IF(INDEX(Rutas!$C:$C,MATCH(B16,Rutas!$A:$A,0))<>INDEX(Conductores!$D:$D,MATCH(C16,Conductores!$A:$A,0)),"REVISAR: el conductor no corresponde a la ruta",IF(OR(INDEX(Vehículos!$E:$E,MATCH(D16,Vehículos!$A:$A,0))="Taller",INDEX(Vehículos!$E:$E,MATCH(D16,Vehículos!$A:$A,0))="Fuera de servicio"),"REVISAR: vehículo no disponible",IF(INDEX(Conductores!$G:$G,MATCH(C16,Conductores!$A:$A,0))<>"Activo","REVISAR: conductor no activo",IF(COUNTIFS($A:$A,A16,$C:$C,C16)>1,"REVISAR: conductor asignado dos veces",IF(COUNTIFS($A:$A,A16,$D:$D,D16)>1,"REVISAR: vehículo asignado dos veces","OK")))))))) | J16: =IF(OR(H16="",H16=0),"",I16/H16) | O16: =IF(AND(OR(K16="En riesgo",K16="Atrasada"),L16=""),"Falta código de motivo",IF(AND(L16="OTR",N16=""),"Explica OTR en las notas",IF(AND(K16="Finalizada",I16<H16,L16=""),"Falta código de motivo",""))) | P16: =IF(OR(D16="",A16=""),"",IF(COUNTIFS(Revision_previa!$B:$B,D16,Revision_previa!$A:$A,">="&A16,Revision_previa!$A:$A,"<"&(A16+1))=0,"Sin revisión",IF(COUNTIFS(Revision_previa!$B:$B,D16,Revision_previa!$A:$A,">="&A16,Revision_previa!$A:$A,"<"&(A16+1),Revision_previa!$D:$D,"Falla")+COUNTIFS(Revision_previa!$B:$B,D16,Revision_previa!$A:$A,">="&A16,Revision_previa!$A:$A,"<"&(A16+1),Revision_previa!$E:$E,"Falla")+COUNTIFS(Revision_previa!$B:$B,D16,Revision_previa!$A:$A,">="&A16,Revision_previa!$A:$A,"<"&(A16+1),Revision_previa!$F:$F,"Falla")+COUNTIFS(Revision_previa!$B:$B,D16,Revision_previa!$A:$A,">="&A16,Revision_previa!$A:$A,"<"&(A16+1),Revision_previa!$H:$H,"Encendido")>0,"No apto","Apto")))
E17: =IF(C17="","",IFERROR(INDEX(Conductores!$B:$B,MATCH(C17,Conductores!$A:$A,0)),"ID no encontrado")) | F17: =IF(B17="","",IFERROR(INDEX(Rutas!$B:$B,MATCH(B17,Rutas!$A:$A,0)),"ID no encontrado")) | G17: =IF(OR(B17="",C17="",D17=""),"",IF(OR(ISNA(MATCH(B17,Rutas!$A:$A,0)),ISNA(MATCH(C17,Conductores!$A:$A,0)),ISNA(MATCH(D17,Vehículos!$A:$A,0))),"REVISAR: ID no encontrado",IF(INDEX(Rutas!$C:$C,MATCH(B17,Rutas!$A:$A,0))<>INDEX(Vehículos!$B:$B,MATCH(D17,Vehículos!$A:$A,0)),"REVISAR: el vehículo no corresponde a la ruta",IF(INDEX(Rutas!$C:$C,MATCH(B17,Rutas!$A:$A,0))<>INDEX(Conductores!$D:$D,MATCH(C17,Conductores!$A:$A,0)),"REVISAR: el conductor no corresponde a la ruta",IF(OR(INDEX(Vehículos!$E:$E,MATCH(D17,Vehículos!$A:$A,0))="Taller",INDEX(Vehículos!$E:$E,MATCH(D17,Vehículos!$A:$A,0))="Fuera de servicio"),"REVISAR: vehículo no disponible",IF(INDEX(Conductores!$G:$G,MATCH(C17,Conductores!$A:$A,0))<>"Activo","REVISAR: conductor no activo",IF(COUNTIFS($A:$A,A17,$C:$C,C17)>1,"REVISAR: conductor asignado dos veces",IF(COUNTIFS($A:$A,A17,$D:$D,D17)>1,"REVISAR: vehículo asignado dos veces","OK")))))))) | J17: =IF(OR(H17="",H17=0),"",I17/H17) | O17: =IF(AND(OR(K17="En riesgo",K17="Atrasada"),L17=""),"Falta código de motivo",IF(AND(L17="OTR",N17=""),"Explica OTR en las notas",IF(AND(K17="Finalizada",I17<H17,L17=""),"Falta código de motivo",""))) | P17: =IF(OR(D17="",A17=""),"",IF(COUNTIFS(Revision_previa!$B:$B,D17,Revision_previa!$A:$A,">="&A17,Revision_previa!$A:$A,"<"&(A17+1))=0,"Sin revisión",IF(COUNTIFS(Revision_previa!$B:$B,D17,Revision_previa!$A:$A,">="&A17,Revision_previa!$A:$A,"<"&(A17+1),Revision_previa!$D:$D,"Falla")+COUNTIFS(Revision_previa!$B:$B,D17,Revision_previa!$A:$A,">="&A17,Revision_previa!$A:$A,"<"&(A17+1),Revision_previa!$E:$E,"Falla")+COUNTIFS(Revision_previa!$B:$B,D17,Revision_previa!$A:$A,">="&A17,Revision_previa!$A:$A,"<"&(A17+1),Revision_previa!$F:$F,"Falla")+COUNTIFS(Revision_previa!$B:$B,D17,Revision_previa!$A:$A,">="&A17,Revision_previa!$A:$A,"<"&(A17+1),Revision_previa!$H:$H,"Encendido")>0,"No apto","Apto")))
... E301: =IF(C301="","",IFERROR(INDEX(Conductores!$B:$B,MATCH(C301,Conductores!$A:$A,0)),"ID no encontrado")) | F301: =IF(B301="","",IFERROR(INDEX(Rutas!$B:$B,MATCH(B301,Rutas!$A:$A,0)),"ID no encontrado")) | G301: =IF(OR(B301="",C301="",D301=""),"",IF(OR(ISNA(MATCH(B301,Rutas!$A:$A,0)),ISNA(MATCH(C301,Conductores!$A:$A,0)),ISNA(MATCH(D301,Vehículos!$A:$A,0))),"REVISAR: ID no encontrado",IF(INDEX(Rutas!$C:$C,MATCH(B301,Rutas!$A:$A,0))<>INDEX(Vehículos!$B:$B,MATCH(D301,Vehículos!$A:$A,0)),"REVISAR: el vehículo no corresponde a la ruta",IF(INDEX(Rutas!$C:$C,MATCH(B301,Rutas!$A:$A,0))<>INDEX(Conductores!$D:$D,MATCH(C301,Conductores!$A:$A,0)),"REVISAR: el conductor no corresponde a la ruta",IF(OR(INDEX(Vehículos!$E:$E,MATCH(D301,Vehículos!$A:$A,0))="Taller",INDEX(Vehículos!$E:$E,MATCH(D301,Vehículos!$A:$A,0))="Fuera de servicio"),"REVISAR: vehículo no disponible",IF(INDEX(Conductores!$G:$G,MATCH(C301,Conductores!$A:$A,0))<>"Activo","REVISAR: conductor no activo",IF(COUNTIFS($A:$A,A301,$C:$C,C301)>1,"REVISAR: conductor asignado dos veces",IF(COUNTIFS($A:$A,A301,$D:$D,D301)>1,"REVISAR: vehículo asignado dos veces","OK")))))))) | J301: =IF(OR(H301="",H301=0),"",I301/H301) | O301: =IF(AND(OR(K301="En riesgo",K301="Atrasada"),L301=""),"Falta código de motivo",IF(AND(L301="OTR",N301=""),"Explica OTR en las notas",IF(AND(K301="Finalizada",I301<H301,L301=""),"Falta código de motivo",""))) | P301: =IF(OR(D301="",A301=""),"",IF(COUNTIFS(Revision_previa!$B:$B,D301,Revision_previa!$A:$A,">="&A301,Revision_previa!$A:$A,"<"&(A301+1))=0,"Sin revisión",IF(COUNTIFS(Revision_previa!$B:$B,D301,Revision_previa!$A:$A,">="&A301,Revision_previa!$A:$A,"<"&(A301+1),Revision_previa!$D:$D,"Falla")+COUNTIFS(Revision_previa!$B:$B,D301,Revision_previa!$A:$A,">="&A301,Revision_previa!$A:$A,"<"&(A301+1),Revision_previa!$E:$E,"Falla")+COUNTIFS(Revision_previa!$B:$B,D301,Revision_previa!$A:$A,">="&A301,Revision_previa!$A:$A,"<"&(A301+1),Revision_previa!$F:$F,"Falla")+COUNTIFS(Revision_previa!$B:$B,D301,Revision_previa!$A:$A,">="&A301,Revision_previa!$A:$A,"<"&(A301+1),Revision_previa!$H:$H,"Encendido")>0,"No apto","Apto")))

Sheet Incidencias
A1: id_incidencia | B1: fecha | C1: hora | D1: id_ruta | E1: id_conductor | F1: codigo_motivo | G1: significado_motivo | H1: gravedad | I1: que_paso | J1: accion_tomada | K1: cliente_informado | L1: resuelta
A2: EX-0001 | B2: 46304 | C2: 0.48611111 | D2: TR-02 | E2: D21 | F2: TRA | G2: =IF(F2="","",IFERROR(INDEX(Listas!$P$2:$P$13,MATCH(F2,Listas!$O$2:$O$13,0)),"Código desconocido")) -> Tráfico o cierre de vía | H2: Media | I2: Accidente en la autopista, camión detenido 40 min | J2: Se llamó al cliente, se movió la hora estimada 45 min y el conductor reanudó a las 12:20 | K2: Sí | L2: Resuelta
G3: =IF(F3="","",IFERROR(INDEX(Listas!$P$2:$P$13,MATCH(F3,Listas!$O$2:$O$13,0)),"Código desconocido"))
G4: =IF(F4="","",IFERROR(INDEX(Listas!$P$2:$P$13,MATCH(F4,Listas!$O$2:$O$13,0)),"Código desconocido"))
G5: =IF(F5="","",IFERROR(INDEX(Listas!$P$2:$P$13,MATCH(F5,Listas!$O$2:$O$13,0)),"Código desconocido"))
G6: =IF(F6="","",IFERROR(INDEX(Listas!$P$2:$P$13,MATCH(F6,Listas!$O$2:$O$13,0)),"Código desconocido"))
G7: =IF(F7="","",IFERROR(INDEX(Listas!$P$2:$P$13,MATCH(F7,Listas!$O$2:$O$13,0)),"Código desconocido"))
G8: =IF(F8="","",IFERROR(INDEX(Listas!$P$2:$P$13,MATCH(F8,Listas!$O$2:$O$13,0)),"Código desconocido"))
G9: =IF(F9="","",IFERROR(INDEX(Listas!$P$2:$P$13,MATCH(F9,Listas!$O$2:$O$13,0)),"Código desconocido"))
G10: =IF(F10="","",IFERROR(INDEX(Listas!$P$2:$P$13,MATCH(F10,Listas!$O$2:$O$13,0)),"Código desconocido"))
G11: =IF(F11="","",IFERROR(INDEX(Listas!$P$2:$P$13,MATCH(F11,Listas!$O$2:$O$13,0)),"Código desconocido"))
G12: =IF(F12="","",IFERROR(INDEX(Listas!$P$2:$P$13,MATCH(F12,Listas!$O$2:$O$13,0)),"Código desconocido"))
G13: =IF(F13="","",IFERROR(INDEX(Listas!$P$2:$P$13,MATCH(F13,Listas!$O$2:$O$13,0)),"Código desconocido"))
G14: =IF(F14="","",IFERROR(INDEX(Listas!$P$2:$P$13,MATCH(F14,Listas!$O$2:$O$13,0)),"Código desconocido"))
... G301: =IF(F301="","",IFERROR(INDEX(Listas!$P$2:$P$13,MATCH(F301,Listas!$O$2:$O$13,0)),"Código desconocido"))

Sheet Revision_previa
A1: marca_temporal | B1: id_vehiculo | C1: id_conductor | D1: neumaticos | E1: luces | F1: frenos | G1: combustible | H1: testigos_aviso | I1: danos_nuevos | J1: observaciones
A2: 46304.299 | B2: V01 | C2: D01 | D2: OK | E2: OK | F2: OK | G2: Tres cuartos | H2: Ninguno | I2: No
A3: 46304.253 | B3: V21 | C3: D21 | D3: OK | E3: OK | F3: OK | G3: Lleno | H3: Ninguno | I3: No
A4: 46304.319 | B4: V15 | C4: D15 | D4: OK | E4: OK | F4: Falla | G4: Medio | H4: Ninguno | I4: No | J4: Ejemplo: frenos con ruido, no sale hasta revisar

Sheet Conductores
A1: id_conductor | B1: nombre | C1: telefono | D1: tipo_vehiculo | E1: categoria_licencia | F1: turno | G1: estado | H1: vencimiento_licencia | I1: vehiculo_habitual
A2: D01 | B2: Juan Martínez | C2: 809-555-0101 | D2: moto | E2: Motocicleta | F2: Mañana | G2: Activo | H2: 46461 | I2: V01
A3: D02 | B3: Luis Almonte | C3: 809-555-0102 | D3: moto | E3: Motocicleta | F3: Tarde | G3: Activo | H3: 46357 | I3: V02
A4: D15 | B4: Mercedes Rodríguez | C4: 809-555-0115 | D4: furgoneta | E4: Vehículo liviano | F4: Mañana | G4: Activo | H4: 46619 | I4: V15
A5: D21 | B5: Yeison Tavárez | C5: 809-555-0121 | D5: camión | E5: Camión pesado | F5: Larga distancia | G5: Activo | H5: 46397 | I5: V21

Sheet Vehículos
A1: id_vehiculo | B1: tipo_vehiculo | C1: placa | D1: combustible | E1: estado | F1: proximo_servicio | G1: odometro_km | H1: notas
A2: V01 | B2: moto | C2: EJEMPLO-01 | D2: gasolina | E2: Disponible | F2: 46331 | G2: 18250
A3: V02 | B3: moto | C3: EJEMPLO-02 | D3: gasolina | E3: Taller | F3: 46307 | G3: 31240 | H3: Pastillas de freno, vuelve el lunes
A4: V15 | B4: furgoneta | C4: EJEMPLO-15 | D4: gasoil | E4: Disponible | F4: 46358 | G4: 74120
A5: V21 | B5: camión | C5: EJEMPLO-21 | D5: gasoil | E5: En uso | F5: 46346 | G5: 212880

Sheet Rutas
A1: id_ruta | B1: zona | C1: tipo_vehiculo | D1: paradas_tipicas | E1: km_tipicos | F1: activa
A2: BK-01 | B2: Distrito Nacional | C2: moto | D2: 24 | E2: 45 | F2: Sí
A3: BK-02 | B3: Zona Colonial | C3: moto | D3: 22 | E3: 38 | F3: Sí
A4: VN-02 | B4: San Cristóbal | C4: furgoneta | D4: 18 | E4: 105 | F4: Sí
A5: TR-02 | B5: Santiago | C5: camión | D5: 8 | E5: 335 | F5: Sí

Sheet Listas
A1: Tipo de vehículo | B1: Estado del vehículo | C1: Estado del conductor | D1: Turno | E1: Categoría de licencia | F1: Combustible | G1: Estado de la ruta | H1: Gravedad | I1: Resuelta | J1: Sí/No | K1: Resultado de revisión | L1: Nivel de combustible | M1: Testigos de aviso | O1: Código de motivo | P1: Significado | Q1: Cuándo usarlo
A2: moto | B2: Disponible | C2: Activo | D2: Mañana | E2: Motocicleta | F2: gasolina | G2: No iniciada | H2: Baja | I2: Abierta | J2: Sí | K2: OK | L2: Lleno | M2: Ninguno | O2: TRA | P2: Tráfico o cierre de vía | Q2: Vías lentas, accidente adelante, calle cerrada
A3: furgoneta | B3: En uso | C3: De permiso | D3: Tarde | E3: Vehículo liviano | F3: gasoil | G3: En tiempo | H3: Media | I3: Resuelta | J3: No | K3: Falla | L3: Tres cuartos | M3: Encendido | O3: CLI | P3: Clima | Q3: Lluvia, tormenta, inundación
A4: camión | B4: Taller | C4: Inactivo | D4: Larga distancia | E4: Camión pesado | G4: En riesgo | H4: Alta | L4: Medio | O4: AVE | P4: Avería del vehículo | Q4: Falla mecánica, goma ponchada, sin combustible
B5: Fuera de servicio | G5: Atrasada | L5: Un cuarto | O5: INC | P5: Accidente o incidente | Q5: Choque, lesión, robo, problema de seguridad
G6: Finalizada | L6: Reserva | O6: AUS | P6: Cliente ausente | Q6: Nadie para recibir la entrega
G7: Cancelada | O7: DIR | P7: Problema de dirección | Q7: Dirección errónea, incompleta o imposible de encontrar
O8: ACE | P8: Acceso bloqueado | Q8: Portón, edificio o calle sin acceso
O9: REC | P9: Entrega rechazada | Q9: El cliente rechaza la entrega
O10: PLA | P10: Plan muy ajustado | Q10: La ruta tenía demasiadas paradas o tiempos poco realistas
O11: CON | P11: Problema del conductor | Q11: Ausente, salida tardía, enfermo, perdido
O12: VEH | P12: Vehículo no listo | Q12: No pasó la revisión previa, sin combustible, no disponible
O13: OTR | P13: Otro | Q13: Usar pocas veces y siempre explicar en las notas
